Workbook
Name Foetal_movements: ALL!$G$1

Sheet ALL
A1: Patient code | B1: Gestation (weeks) | C1: Gestation (days) | D1: Maternal age | E1: Parity | G1: Foetal movements | H1: Maternal comorbidities | I1: Maternal comorbidities Other | J1: Normal scans | K1: Normal dopplers | M1: CTG done | N1: Liquor- meconium | O1: Chorioamnionitis | P1: PROM (>18hours) | Q1: RFFS | R1: Sentinel event | T1: Delivery | U1: Birth weight (grams) | V1: Apgars 1 | W1: Apgars 5 | X1: Apgars 10 | Y1: Delayed cord clamping | Z1: Cord arterial pH | AA1: Cord arterial BE | AB1: Cord arterial lactate | AD1: Intubated at delivery | AE1: Cardiac compressions | AF1: Drugs given | AG1: Ward | AH1: Gas repeated? | AI1: Age at repeated gas (hours) | AJ1: Repeated lactate | AK1: Age gas normalised (hours) | AL1: Hypoglycaemia | AM1: Admitted to NICU | AN1: Age at discharge home (days) | AO1: Unit level questionnaire filled | AP1: Local guideline for cord gas sampling available | AQ1: Local guideline for fetal acidosis available
A2: =HYPERLINK("#'Evidence'!A2",'Evidence'!D2) | B2: =HYPERLINK("#'Evidence'!A3",'Evidence'!D3) | C2: =HYPERLINK("#'Evidence'!A4",'Evidence'!D4) | D2: =HYPERLINK("#'Evidence'!A5",'Evidence'!D5) | E2: =HYPERLINK("#'Evidence'!A6",'Evidence'!D6) | G2: =HYPERLINK("#'Evidence'!A7",'Evidence'!D7) | H2: =HYPERLINK("#'Evidence'!A8",'Evidence'!D8) | I2: =HYPERLINK("#'Evidence'!A9",'Evidence'!D9) | J2: =HYPERLINK("#'Evidence'!A10",'Evidence'!D10) | K2: =HYPERLINK("#'Evidence'!A11",'Evidence'!D11) | M2: =HYPERLINK("#'Evidence'!A12",'Evidence'!D12) | N2: =HYPERLINK("#'Evidence'!A13",'Evidence'!D13) | O2: =HYPERLINK("#'Evidence'!A14",'Evidence'!D14) | P2: =HYPERLINK("#'Evidence'!A15",'Evidence'!D15) | Q2: =HYPERLINK("#'Evidence'!A16",'Evidence'!D16) | R2: =HYPERLINK("#'Evidence'!A17",'Evidence'!D17) | T2: =HYPERLINK("#'Evidence'!A18",'Evidence'!D18) | U2: =HYPERLINK("#'Evidence'!A19",'Evidence'!D19) | V2: =HYPERLINK("#'Evidence'!A20",'Evidence'!D20) | W2: =HYPERLINK("#'Evidence'!A21",'Evidence'!D21) | X2: =HYPERLINK("#'Evidence'!A22",'Evidence'!D22) | Y2: =HYPERLINK("#'Evidence'!A23",'Evidence'!D23) | Z2: =HYPERLINK("#'Evidence'!A24",'Evidence'!D24) | AA2: =HYPERLINK("#'Evidence'!A25",'Evidence'!D25) | AB2: =HYPERLINK("#'Evidence'!A26",'Evidence'!D26) | AD2: =HYPERLINK("#'Evidence'!A27",'Evidence'!D27) | AE2: =HYPERLINK("#'Evidence'!A28",'Evidence'!D28) | AF2: =HYPERLINK("#'Evidence'!A29",'Evidence'!D29) | AG2: =HYPERLINK("#'Evidence'!A30",'Evidence'!D30) | AH2: =HYPERLINK("#'Evidence'!A31",'Evidence'!D31) | AI2: =HYPERLINK("#'Evidence'!A32",'Evidence'!D32) | AJ2: =HYPERLINK("#'Evidence'!A33",'Evidence'!D33) | AK2: =HYPERLINK("#'Evidence'!A34",'Evidence'!D34) | AL2: =HYPERLINK("#'Evidence'!A35",'Evidence'!D35) | AM2: =HYPERLINK("#'Evidence'!A36",'Evidence'!D36) | AN2: =HYPERLINK("#'Evidence'!A37",'Evidence'!D37) | AO2: =HYPERLINK("#'Evidence'!A38",'Evidence'!D38) | AP2: =HYPERLINK("#'Evidence'!A39",'Evidence'!D39) | AQ2: =HYPERLINK("#'Evidence'!A40",'Evidence'!D40)
B3: =HYPERLINK("#'Evidence'!A41",'Evidence'!D41) | C3: =HYPERLINK("#'Evidence'!A42",'Evidence'!D42) | D3: =HYPERLINK("#'Evidence'!A43",'Evidence'!D43) | E3: =HYPERLINK("#'Evidence'!A44",'Evidence'!D44) | G3: =HYPERLINK("#'Evidence'!A45",'Evidence'!D45) | H3: =HYPERLINK("#'Evidence'!A46",'Evidence'!D46) | I3: =HYPERLINK("#'Evidence'!A47",'Evidence'!D47) | J3: =HYPERLINK("#'Evidence'!A48",'Evidence'!D48) | K3: =HYPERLINK("#'Evidence'!A49",'Evidence'!D49) | M3: =HYPERLINK("#'Evidence'!A50",'Evidence'!D50) | N3: =HYPERLINK("#'Evidence'!A51",'Evidence'!D51) | O3: =HYPERLINK("#'Evidence'!A52",'Evidence'!D52) | P3: =HYPERLINK("#'Evidence'!A53",'Evidence'!D53) | Q3: =HYPERLINK("#'Evidence'!A54",'Evidence'!D54) | R3: =HYPERLINK("#'Evidence'!A55",'Evidence'!D55) | T3: =HYPERLINK("#'Evidence'!A56",'Evidence'!D56) | U3: =HYPERLINK("#'Evidence'!A57",'Evidence'!D57) | V3: =HYPERLINK("#'Evidence'!A58",'Evidence'!D58) | W3: =HYPERLINK("#'Evidence'!A59",'Evidence'!D59) | X3: =HYPERLINK("#'Evidence'!A60",'Evidence'!D60) | Y3: =HYPERLINK("#'Evidence'!A61",'Evidence'!D61) | Z3: =HYPERLINK("#'Evidence'!A62",'Evidence'!D62) | AA3: =HYPERLINK("#'Evidence'!A63",'Evidence'!D63) | AB3: =HYPERLINK("#'Evidence'!A64",'Evidence'!D64) | AD3: =HYPERLINK("#'Evidence'!A65",'Evidence'!D65) | AE3: =HYPERLINK("#'Evidence'!A66",'Evidence'!D66) | AF3: =HYPERLINK("#'Evidence'!A67",'Evidence'!D67) | AG3: =HYPERLINK("#'Evidence'!A68",'Evidence'!D68) | AH3: =HYPERLINK("#'Evidence'!A69",'Evidence'!D69) | AI3: =HYPERLINK("#'Evidence'!A70",'Evidence'!D70) | AJ3: =HYPERLINK("#'Evidence'!A71",'Evidence'!D71) | AK3: =HYPERLINK("#'Evidence'!A72",'Evidence'!D72) | AL3: =HYPERLINK("#'Evidence'!A73",'Evidence'!D73) | AM3: =HYPERLINK("#'Evidence'!A74",'Evidence'!D74) | AN3: =HYPERLINK("#'Evidence'!A75",'Evidence'!D75) | AO3: =HYPERLINK("#'Evidence'!A76",'Evidence'!D76) | AP3: =HYPERLINK("#'Evidence'!A77",'Evidence'!D77) | AQ3: =HYPERLINK("#'Evidence'!A78",'Evidence'!D78)
B4: =HYPERLINK("#'Evidence'!A79",'Evidence'!D79) | C4: =HYPERLINK("#'Evidence'!A80",'Evidence'!D80) | D4: =HYPERLINK("#'Evidence'!A81",'Evidence'!D81) | E4: =HYPERLINK("#'Evidence'!A82",'Evidence'!D82) | G4: =HYPERLINK("#'Evidence'!A83",'Evidence'!D83) | H4: =HYPERLINK("#'Evidence'!A84",'Evidence'!D84) | I4: =HYPERLINK("#'Evidence'!A85",'Evidence'!D85) | J4: =HYPERLINK("#'Evidence'!A86",'Evidence'!D86) | K4: =HYPERLINK("#'Evidence'!A87",'Evidence'!D87) | M4: =HYPERLINK("#'Evidence'!A88",'Evidence'!D88) | N4: =HYPERLINK("#'Evidence'!A89",'Evidence'!D89) | O4: =HYPERLINK("#'Evidence'!A90",'Evidence'!D90) | P4: =HYPERLINK("#'Evidence'!A91",'Evidence'!D91) | Q4: =HYPERLINK("#'Evidence'!A92",'Evidence'!D92) | R4: =HYPERLINK("#'Evidence'!A93",'Evidence'!D93) | T4: =HYPERLINK("#'Evidence'!A94",'Evidence'!D94) | U4: =HYPERLINK("#'Evidence'!A95",'Evidence'!D95) | V4: =HYPERLINK("#'Evidence'!A96",'Evidence'!D96) | W4: =HYPERLINK("#'Evidence'!A97",'Evidence'!D97) | X4: =HYPERLINK("#'Evidence'!A98",'Evidence'!D98) | Y4: =HYPERLINK("#'Evidence'!A99",'Evidence'!D99) | Z4: =HYPERLINK("#'Evidence'!A100",'Evidence'!D100) | AA4: =HYPERLINK("#'Evidence'!A101",'Evidence'!D101) | AB4: =HYPERLINK("#'Evidence'!A102",'Evidence'!D102) | AD4: =HYPERLINK("#'Evidence'!A103",'Evidence'!D103) | AE4: =HYPERLINK("#'Evidence'!A104",'Evidence'!D104) | AF4: =HYPERLINK("#'Evidence'!A105",'Evidence'!D105) | AG4: =HYPERLINK("#'Evidence'!A106",'Evidence'!D106) | AH4: =HYPERLINK("#'Evidence'!A107",'Evidence'!D107) | AI4: =HYPERLINK("#'Evidence'!A108",'Evidence'!D108) | AJ4: =HYPERLINK("#'Evidence'!A109",'Evidence'!D109) | AK4: =HYPERLINK("#'Evidence'!A110",'Evidence'!D110) | AL4: =HYPERLINK("#'Evidence'!A111",'Evidence'!D111) | AM4: =HYPERLINK("#'Evidence'!A112",'Evidence'!D112) | AN4: =HYPERLINK("#'Evidence'!A113",'Evidence'!D113) | AO4: =HYPERLINK("#'Evidence'!A114",'Evidence'!D114) | AP4: =HYPERLINK("#'Evidence'!A115",'Evidence'!D115) | AQ4: =HYPERLINK("#'Evidence'!A116",'Evidence'!D116)
B5: =HYPERLINK("#'Evidence'!A117",'Evidence'!D117) | C5: =HYPERLINK("#'Evidence'!A118",'Evidence'!D118) | D5: =HYPERLINK("#'Evidence'!A119",'Evidence'!D119) | E5: =HYPERLINK("#'Evidence'!A120",'Evidence'!D120) | G5: =HYPERLINK("#'Evidence'!A121",'Evidence'!D121) | H5: =HYPERLINK("#'Evidence'!A122",'Evidence'!D122) | I5: =HYPERLINK("#'Evidence'!A123",'Evidence'!D123) | J5: =HYPERLINK("#'Evidence'!A124",'Evidence'!D124) | K5: =HYPERLINK("#'Evidence'!A125",'Evidence'!D125) | M5: =HYPERLINK("#'Evidence'!A126",'Evidence'!D126) | N5: =HYPERLINK("#'Evidence'!A127",'Evidence'!D127) | O5: =HYPERLINK("#'Evidence'!A128",'Evidence'!D128) | P5: =HYPERLINK("#'Evidence'!A129",'Evidence'!D129) | Q5: =HYPERLINK("#'Evidence'!A130",'Evidence'!D130) | R5: =HYPERLINK("#'Evidence'!A131",'Evidence'!D131) | T5: =HYPERLINK("#'Evidence'!A132",'Evidence'!D132) | U5: =HYPERLINK("#'Evidence'!A133",'Evidence'!D133) | V5: =HYPERLINK("#'Evidence'!A134",'Evidence'!D134) | W5: =HYPERLINK("#'Evidence'!A135",'Evidence'!D135) | X5: =HYPERLINK("#'Evidence'!A136",'Evidence'!D136) | Y5: =HYPERLINK("#'Evidence'!A137",'Evidence'!D137) | Z5: =HYPERLINK("#'Evidence'!A138",'Evidence'!D138) | AA5: =HYPERLINK("#'Evidence'!A139",'Evidence'!D139) | AB5: =HYPERLINK("#'Evidence'!A140",'Evidence'!D140) | AD5: =HYPERLINK("#'Evidence'!A141",'Evidence'!D141) | AE5: =HYPERLINK("#'Evidence'!A142",'Evidence'!D142) | AF5: =HYPERLINK("#'Evidence'!A143",'Evidence'!D143) | AG5: =HYPERLINK("#'Evidence'!A144",'Evidence'!D144) | AH5: =HYPERLINK("#'Evidence'!A145",'Evidence'!D145) | AI5: =HYPERLINK("#'Evidence'!A146",'Evidence'!D146) | AJ5: =HYPERLINK("#'Evidence'!A147",'Evidence'!D147) | AK5: =HYPERLINK("#'Evidence'!A148",'Evidence'!D148) | AL5: =HYPERLINK("#'Evidence'!A149",'Evidence'!D149) | AM5: =HYPERLINK("#'Evidence'!A150",'Evidence'!D150) | AN5: =HYPERLINK("#'Evidence'!A151",'Evidence'!D151) | AO5: =HYPERLINK("#'Evidence'!A152",'Evidence'!D152) | AP5: =HYPERLINK("#'Evidence'!A153",'Evidence'!D153) | AQ5: =HYPERLINK("#'Evidence'!A154",'Evidence'!D154)
B6: =HYPERLINK("#'Evidence'!A155",'Evidence'!D155) | C6: =HYPERLINK("#'Evidence'!A156",'Evidence'!D156) | D6: =HYPERLINK("#'Evidence'!A157",'Evidence'!D157) | E6: =HYPERLINK("#'Evidence'!A158",'Evidence'!D158) | G6: =HYPERLINK("#'Evidence'!A159",'Evidence'!D159) | H6: =HYPERLINK("#'Evidence'!A160",'Evidence'!D160) | I6: =HYPERLINK("#'Evidence'!A161",'Evidence'!D161) | J6: =HYPERLINK("#'Evidence'!A162",'Evidence'!D162) | K6: =HYPERLINK("#'Evidence'!A163",'Evidence'!D163) | M6: =HYPERLINK("#'Evidence'!A164",'Evidence'!D164) | N6: =HYPERLINK("#'Evidence'!A165",'Evidence'!D165) | O6: =HYPERLINK("#'Evidence'!A166",'Evidence'!D166) | P6: =HYPERLINK("#'Evidence'!A167",'Evidence'!D167) | Q6: =HYPERLINK("#'Evidence'!A168",'Evidence'!D168) | R6: =HYPERLINK("#'Evidence'!A169",'Evidence'!D169) | T6: =HYPERLINK("#'Evidence'!A170",'Evidence'!D170) | U6: =HYPERLINK("#'Evidence'!A171",'Evidence'!D171) | V6: =HYPERLINK("#'Evidence'!A172",'Evidence'!D172) | W6: =HYPERLINK("#'Evidence'!A173",'Evidence'!D173) | X6: =HYPERLINK("#'Evidence'!A174",'Evidence'!D174) | Y6: =HYPERLINK("#'Evidence'!A175",'Evidence'!D175) | Z6: =HYPERLINK("#'Evidence'!A176",'Evidence'!D176) | AA6: =HYPERLINK("#'Evidence'!A177",'Evidence'!D177) | AB6: =HYPERLINK("#'Evidence'!A178",'Evidence'!D178) | AD6: =HYPERLINK("#'Evidence'!A179",'Evidence'!D179) | AE6: =HYPERLINK("#'Evidence'!A180",'Evidence'!D180) | AF6: =HYPERLINK("#'Evidence'!A181",'Evidence'!D181) | AG6: =HYPERLINK("#'Evidence'!A182",'Evidence'!D182) | AH6: =HYPERLINK("#'Evidence'!A183",'Evidence'!D183) | AI6: =HYPERLINK("#'Evidence'!A184",'Evidence'!D184) | AJ6: =HYPERLINK("#'Evidence'!A185",'Evidence'!D185) | AK6: =HYPERLINK("#'Evidence'!A186",'Evidence'!D186) | AL6: =HYPERLINK("#'Evidence'!A187",'Evidence'!D187) | AM6: =HYPERLINK("#'Evidence'!A188",'Evidence'!D188) | AN6: =HYPERLINK("#'Evidence'!A189",'Evidence'!D189) | AO6: =HYPERLINK("#'Evidence'!A190",'Evidence'!D190) | AP6: =HYPERLINK("#'Evidence'!A191",'Evidence'!D191) | AQ6: =HYPERLINK("#'Evidence'!A192",'Evidence'!D192)
B7: =HYPERLINK("#'Evidence'!A193",'Evidence'!D193) | C7: =HYPERLINK("#'Evidence'!A194",'Evidence'!D194) | D7: =HYPERLINK("#'Evidence'!A195",'Evidence'!D195) | E7: =HYPERLINK("#'Evidence'!A196",'Evidence'!D196) | G7: =HYPERLINK("#'Evidence'!A197",'Evidence'!D197) | H7: =HYPERLINK("#'Evidence'!A198",'Evidence'!D198) | I7: =HYPERLINK("#'Evidence'!A199",'Evidence'!D199) | J7: =HYPERLINK("#'Evidence'!A200",'Evidence'!D200) | K7: =HYPERLINK("#'Evidence'!A201",'Evidence'!D201) | M7: =HYPERLINK("#'Evidence'!A202",'Evidence'!D202) | N7: =HYPERLINK("#'Evidence'!A203",'Evidence'!D203) | O7: =HYPERLINK("#'Evidence'!A204",'Evidence'!D204) | P7: =HYPERLINK("#'Evidence'!A205",'Evidence'!D205) | Q7: =HYPERLINK("#'Evidence'!A206",'Evidence'!D206) | R7: =HYPERLINK("#'Evidence'!A207",'Evidence'!D207) | T7: =HYPERLINK("#'Evidence'!A208",'Evidence'!D208) | U7: =HYPERLINK("#'Evidence'!A209",'Evidence'!D209) | V7: =HYPERLINK("#'Evidence'!A210",'Evidence'!D210) | W7: =HYPERLINK("#'Evidence'!A211",'Evidence'!D211) | X7: =HYPERLINK("#'Evidence'!A212",'Evidence'!D212) | Y7: =HYPERLINK("#'Evidence'!A213",'Evidence'!D213) | Z7: =HYPERLINK("#'Evidence'!A214",'Evidence'!D214) | AA7: =HYPERLINK("#'Evidence'!A215",'Evidence'!D215) | AB7: =HYPERLINK("#'Evidence'!A216",'Evidence'!D216) | AD7: =HYPERLINK("#'Evidence'!A217",'Evidence'!D217) | AE7: =HYPERLINK("#'Evidence'!A218",'Evidence'!D218) | AF7: =HYPERLINK("#'Evidence'!A219",'Evidence'!D219) | AG7: =HYPERLINK("#'Evidence'!A220",'Evidence'!D220) | AH7: =HYPERLINK("#'Evidence'!A221",'Evidence'!D221) | AI7: =HYPERLINK("#'Evidence'!A222",'Evidence'!D222) | AJ7: =HYPERLINK("#'Evidence'!A223",'Evidence'!D223) | AK7: =HYPERLINK("#'Evidence'!A224",'Evidence'!D224) | AL7: =HYPERLINK("#'Evidence'!A225",'Evidence'!D225) | AM7: =HYPERLINK("#'Evidence'!A226",'Evidence'!D226) | AN7: =HYPERLINK("#'Evidence'!A227",'Evidence'!D227) | AO7: =HYPERLINK("#'Evidence'!A228",'Evidence'!D228) | AP7: =HYPERLINK("#'Evidence'!A229",'Evidence'!D229) | AQ7: =HYPERLINK("#'Evidence'!A230",'Evidence'!D230)
B8: =HYPERLINK("#'Evidence'!A231",'Evidence'!D231) | C8: =HYPERLINK("#'Evidence'!A232",'Evidence'!D232) | D8: =HYPERLINK("#'Evidence'!A233",'Evidence'!D233) | E8: =HYPERLINK("#'Evidence'!A234",'Evidence'!D234) | G8: =HYPERLINK("#'Evidence'!A235",'Evidence'!D235) | H8: =HYPERLINK("#'Evidence'!A236",'Evidence'!D236) | I8: =HYPERLINK("#'Evidence'!A237",'Evidence'!D237) | J8: =HYPERLINK("#'Evidence'!A238",'Evidence'!D238) | K8: =HYPERLINK("#'Evidence'!A239",'Evidence'!D239) | M8: =HYPERLINK("#'Evidence'!A240",'Evidence'!D240) | N8: =HYPERLINK("#'Evidence'!A241",'Evidence'!D241) | O8: =HYPERLINK("#'Evidence'!A242",'Evidence'!D242) | P8: =HYPERLINK("#'Evidence'!A243",'Evidence'!D243) | Q8: =HYPERLINK("#'Evidence'!A244",'Evidence'!D244) | R8: =HYPERLINK("#'Evidence'!A245",'Evidence'!D245) | T8: =HYPERLINK("#'Evidence'!A246",'Evidence'!D246) | U8: =HYPERLINK("#'Evidence'!A247",'Evidence'!D247) | V8: =HYPERLINK("#'Evidence'!A248",'Evidence'!D248) | W8: =HYPERLINK("#'Evidence'!A249",'Evidence'!D249) | X8: =HYPERLINK("#'Evidence'!A250",'Evidence'!D250) | Y8: =HYPERLINK("#'Evidence'!A251",'Evidence'!D251) | Z8: =HYPERLINK("#'Evidence'!A252",'Evidence'!D252) | AA8: =HYPERLINK("#'Evidence'!A253",'Evidence'!D253) | AB8: =HYPERLINK("#'Evidence'!A254",'Evidence'!D254) | AD8: =HYPERLINK("#'Evidence'!A255",'Evidence'!D255) | AE8: =HYPERLINK("#'Evidence'!A256",'Evidence'!D256) | AF8: =HYPERLINK("#'Evidence'!A257",'Evidence'!D257) | AG8: =HYPERLINK("#'Evidence'!A258",'Evidence'!D258) | AH8: =HYPERLINK("#'Evidence'!A259",'Evidence'!D259) | AI8: =HYPERLINK("#'Evidence'!A260",'Evidence'!D260) | AJ8: =HYPERLINK("#'Evidence'!A261",'Evidence'!D261) | AK8: =HYPERLINK("#'Evidence'!A262",'Evidence'!D262) | AL8: =HYPERLINK("#'Evidence'!A263",'Evidence'!D263) | AM8: =HYPERLINK("#'Evidence'!A264",'Evidence'!D264) | AN8: =HYPERLINK("#'Evidence'!A265",'Evidence'!D265) | AO8: =HYPERLINK("#'Evidence'!A266",'Evidence'!D266) | AP8: =HYPERLINK("#'Evidence'!A267",'Evidence'!D267) | AQ8: =HYPERLINK("#'Evidence'!A268",'Evidence'!D268)
B9: =HYPERLINK("#'Evidence'!A269",'Evidence'!D269) | C9: =HYPERLINK("#'Evidence'!A270",'Evidence'!D270) | D9: =HYPERLINK("#'Evidence'!A271",'Evidence'!D271) | E9: =HYPERLINK("#'Evidence'!A272",'Evidence'!D272) | G9: =HYPERLINK("#'Evidence'!A273",'Evidence'!D273) | H9: =HYPERLINK("#'Evidence'!A274",'Evidence'!D274) | I9: =HYPERLINK("#'Evidence'!A275",'Evidence'!D275) | J9: =HYPERLINK("#'Evidence'!A276",'Evidence'!D276) | K9: =HYPERLINK("#'Evidence'!A277",'Evidence'!D277) | M9: =HYPERLINK("#'Evidence'!A278",'Evidence'!D278) | N9: =HYPERLINK("#'Evidence'!A279",'Evidence'!D279) | O9: =HYPERLINK("#'Evidence'!A280",'Evidence'!D280) | P9: =HYPERLINK("#'Evidence'!A281",'Evidence'!D281) | Q9: =HYPERLINK("#'Evidence'!A282",'Evidence'!D282) | R9: =HYPERLINK("#'Evidence'!A283",'Evidence'!D283) | T9: =HYPERLINK("#'Evidence'!A284",'Evidence'!D284) | U9: =HYPERLINK("#'Evidence'!A285",'Evidence'!D285) | V9: =HYPERLINK("#'Evidence'!A286",'Evidence'!D286) | W9: =HYPERLINK("#'Evidence'!A287",'Evidence'!D287) | X9: =HYPERLINK("#'Evidence'!A288",'Evidence'!D288) | Y9: =HYPERLINK("#'Evidence'!A289",'Evidence'!D289) | Z9: =HYPERLINK("#'Evidence'!A290",'Evidence'!D290) | AA9: =HYPERLINK("#'Evidence'!A291",'Evidence'!D291) | AB9: =HYPERLINK("#'Evidence'!A292",'Evidence'!D292) | AD9: =HYPERLINK("#'Evidence'!A293",'Evidence'!D293) | AE9: =HYPERLINK("#'Evidence'!A294",'Evidence'!D294) | AF9: =HYPERLINK("#'Evidence'!A295",'Evidence'!D295) | AG9: =HYPERLINK("#'Evidence'!A296",'Evidence'!D296) | AH9: =HYPERLINK("#'Evidence'!A297",'Evidence'!D297) | AI9: =HYPERLINK("#'Evidence'!A298",'Evidence'!D298) | AJ9: =HYPERLINK("#'Evidence'!A299",'Evidence'!D299) | AK9: =HYPERLINK("#'Evidence'!A300",'Evidence'!D300) | AL9: =HYPERLINK("#'Evidence'!A301",'Evidence'!D301) | AM9: =HYPERLINK("#'Evidence'!A302",'Evidence'!D302) | AN9: =HYPERLINK("#'Evidence'!A303",'Evidence'!D303) | AO9: =HYPERLINK("#'Evidence'!A304",'Evidence'!D304) | AP9: =HYPERLINK("#'Evidence'!A305",'Evidence'!D305) | AQ9: =HYPERLINK("#'Evidence'!A306",'Evidence'!D306)
B10: =HYPERLINK("#'Evidence'!A307",'Evidence'!D307) | C10: =HYPERLINK("#'Evidence'!A308",'Evidence'!D308) | D10: =HYPERLINK("#'Evidence'!A309",'Evidence'!D309) | E10: =HYPERLINK("#'Evidence'!A310",'Evidence'!D310) | G10: =HYPERLINK("#'Evidence'!A311",'Evidence'!D311) | H10: =HYPERLINK("#'Evidence'!A312",'Evidence'!D312) | I10: =HYPERLINK("#'Evidence'!A313",'Evidence'!D313) | J10: =HYPERLINK("#'Evidence'!A314",'Evidence'!D314) | K10: =HYPERLINK("#'Evidence'!A315",'Evidence'!D315) | M10: =HYPERLINK("#'Evidence'!A316",'Evidence'!D316) | N10: =HYPERLINK("#'Evidence'!A317",'Evidence'!D317) | O10: =HYPERLINK("#'Evidence'!A318",'Evidence'!D318) | P10: =HYPERLINK("#'Evidence'!A319",'Evidence'!D319) | Q10: =HYPERLINK("#'Evidence'!A320",'Evidence'!D320) | R10: =HYPERLINK("#'Evidence'!A321",'Evidence'!D321) | T10: =HYPERLINK("#'Evidence'!A322",'Evidence'!D322) | U10: =HYPERLINK("#'Evidence'!A323",'Evidence'!D323) | V10: =HYPERLINK("#'Evidence'!A324",'Evidence'!D324) | W10: =HYPERLINK("#'Evidence'!A325",'Evidence'!D325) | X10: =HYPERLINK("#'Evidence'!A326",'Evidence'!D326) | Y10: =HYPERLINK("#'Evidence'!A327",'Evidence'!D327) | Z10: =HYPERLINK("#'Evidence'!A328",'Evidence'!D328) | AA10: =HYPERLINK("#'Evidence'!A329",'Evidence'!D329) | AB10: =HYPERLINK("#'Evidence'!A330",'Evidence'!D330) | AD10: =HYPERLINK("#'Evidence'!A331",'Evidence'!D331) | AE10: =HYPERLINK("#'Evidence'!A332",'Evidence'!D332) | AF10: =HYPERLINK("#'Evidence'!A333",'Evidence'!D333) | AG10: =HYPERLINK("#'Evidence'!A334",'Evidence'!D334) | AH10: =HYPERLINK("#'Evidence'!A335",'Evidence'!D335) | AI10: =HYPERLINK("#'Evidence'!A336",'Evidence'!D336) | AJ10: =HYPERLINK("#'Evidence'!A337",'Evidence'!D337) | AK10: =HYPERLINK("#'Evidence'!A338",'Evidence'!D338) | AL10: =HYPERLINK("#'Evidence'!A339",'Evidence'!D339) | AM10: =HYPERLINK("#'Evidence'!A340",'Evidence'!D340) | AN10: =HYPERLINK("#'Evidence'!A341",'Evidence'!D341) | AO10: =HYPERLINK("#'Evidence'!A342",'Evidence'!D342) | AP10: =HYPERLINK("#'Evidence'!A343",'Evidence'!D343) | AQ10: =HYPERLINK("#'Evidence'!A344",'Evidence'!D344)
B11: =HYPERLINK("#'Evidence'!A345",'Evidence'!D345) | C11: =HYPERLINK("#'Evidence'!A346",'Evidence'!D346) | D11: =HYPERLINK("#'Evidence'!A347",'Evidence'!D347) | E11: =HYPERLINK("#'Evidence'!A348",'Evidence'!D348) | G11: =HYPERLINK("#'Evidence'!A349",'Evidence'!D349) | H11: =HYPERLINK("#'Evidence'!A350",'Evidence'!D350) | I11: =HYPERLINK("#'Evidence'!A351",'Evidence'!D351) | J11: =HYPERLINK("#'Evidence'!A352",'Evidence'!D352) | K11: =HYPERLINK("#'Evidence'!A353",'Evidence'!D353) | M11: =HYPERLINK("#'Evidence'!A354",'Evidence'!D354) | N11: =HYPERLINK("#'Evidence'!A355",'Evidence'!D355) | O11: =HYPERLINK("#'Evidence'!A356",'Evidence'!D356) | P11: =HYPERLINK("#'Evidence'!A357",'Evidence'!D357) | Q11: =HYPERLINK("#'Evidence'!A358",'Evidence'!D358) | R11: =HYPERLINK("#'Evidence'!A359",'Evidence'!D359) | T11: =HYPERLINK("#'Evidence'!A360",'Evidence'!D360) | U11: =HYPERLINK("#'Evidence'!A361",'Evidence'!D361) | V11: =HYPERLINK("#'Evidence'!A362",'Evidence'!D362) | W11: =HYPERLINK("#'Evidence'!A363",'Evidence'!D363) | X11: =HYPERLINK("#'Evidence'!A364",'Evidence'!D364) | Y11: =HYPERLINK("#'Evidence'!A365",'Evidence'!D365) | Z11: =HYPERLINK("#'Evidence'!A366",'Evidence'!D366) | AA11: =HYPERLINK("#'Evidence'!A367",'Evidence'!D367) | AB11: =HYPERLINK("#'Evidence'!A368",'Evidence'!D368) | AD11: =HYPERLINK("#'Evidence'!A369",'Evidence'!D369) | AE11: =HYPERLINK("#'Evidence'!A370",'Evidence'!D370) | AF11: =HYPERLINK("#'Evidence'!A371",'Evidence'!D371) | AG11: =HYPERLINK("#'Evidence'!A372",'Evidence'!D372) | AH11: =HYPERLINK("#'Evidence'!A373",'Evidence'!D373) | AI11: =HYPERLINK("#'Evidence'!A374",'Evidence'!D374) | AJ11: =HYPERLINK("#'Evidence'!A375",'Evidence'!D375) | AK11: =HYPERLINK("#'Evidence'!A376",'Evidence'!D376) | AL11: =HYPERLINK("#'Evidence'!A377",'Evidence'!D377) | AM11: =HYPERLINK("#'Evidence'!A378",'Evidence'!D378) | AN11: =HYPERLINK("#'Evidence'!A379",'Evidence'!D379) | AO11: =HYPERLINK("#'Evidence'!A380",'Evidence'!D380) | AP11: =HYPERLINK("#'Evidence'!A381",'Evidence'!D381) | AQ11: =HYPERLINK("#'Evidence'!A382",'Evidence'!D382)

Sheet NICU
A1: Age (hours) at NNU admission | B1: Cooled | C1: Age at cooling (hours) | D1: Transferred out | E1: CFM | F1: Seizures | G1: Clinical seizures | H1: Electrographic seizure | I1: MRI injury | K1: Duration of admission in NICU (days) | L1: Age at discharge home (days) | M1: Feeding on discharge | N1: Abnormal neurology at discharge
A2: =HYPERLINK("#'Evidence'!A383",'Evidence'!D383) | B2: =HYPERLINK("#'Evidence'!A384",'Evidence'!D384) | C2: =HYPERLINK("#'Evidence'!A385",'Evidence'!D385) | D2: =HYPERLINK("#'Evidence'!A386",'Evidence'!D386) | E2: =HYPERLINK("#'Evidence'!A387",'Evidence'!D387) | F2: =HYPERLINK("#'Evidence'!A388",'Evidence'!D388) | G2: =HYPERLINK("#'Evidence'!A389",'Evidence'!D389) | H2: =HYPERLINK("#'Evidence'!A390",'Evidence'!D390) | I2: =HYPERLINK("#'Evidence'!A391",'Evidence'!D391) | K2: =HYPERLINK("#'Evidence'!A392",'Evidence'!D392) | L2: =HYPERLINK("#'Evidence'!A393",'Evidence'!D393) | M2: =HYPERLINK("#'Evidence'!A394",'Evidence'!D394) | N2: =HYPERLINK("#'Evidence'!A395",'Evidence'!D395)
A3: =HYPERLINK("#'Evidence'!A396",'Evidence'!D396) | B3: =HYPERLINK("#'Evidence'!A397",'Evidence'!D397) | C3: =HYPERLINK("#'Evidence'!A398",'Evidence'!D398) | D3: =HYPERLINK("#'Evidence'!A399",'Evidence'!D399) | E3: =HYPERLINK("#'Evidence'!A400",'Evidence'!D400) | F3: =HYPERLINK("#'Evidence'!A401",'Evidence'!D401) | G3: =HYPERLINK("#'Evidence'!A402",'Evidence'!D402) | H3: =HYPERLINK("#'Evidence'!A403",'Evidence'!D403) | I3: =HYPERLINK("#'Evidence'!A404",'Evidence'!D404) | K3: =HYPERLINK("#'Evidence'!A405",'Evidence'!D405) | L3: =HYPERLINK("#'Evidence'!A406",'Evidence'!D406) | M3: =HYPERLINK("#'Evidence'!A407",'Evidence'!D407) | N3: =HYPERLINK("#'Evidence'!A408",'Evidence'!D408)
A4: =HYPERLINK("#'Evidence'!A409",'Evidence'!D409) | B4: =HYPERLINK("#'Evidence'!A410",'Evidence'!D410) | C4: =HYPERLINK("#'Evidence'!A411",'Evidence'!D411) | D4: =HYPERLINK("#'Evidence'!A412",'Evidence'!D412) | E4: =HYPERLINK("#'Evidence'!A413",'Evidence'!D413) | F4: =HYPERLINK("#'Evidence'!A414",'Evidence'!D414) | G4: =HYPERLINK("#'Evidence'!A415",'Evidence'!D415) | H4: =HYPERLINK("#'Evidence'!A416",'Evidence'!D416) | I4: =HYPERLINK("#'Evidence'!A417",'Evidence'!D417) | K4: =HYPERLINK("#'Evidence'!A418",'Evidence'!D418) | L4: =HYPERLINK("#'Evidence'!A419",'Evidence'!D419) | M4: =HYPERLINK("#'Evidence'!A420",'Evidence'!D420) | N4: =HYPERLINK("#'Evidence'!A421",'Evidence'!D421)
A5: =HYPERLINK("#'Evidence'!A422",'Evidence'!D422) | B5: =HYPERLINK("#'Evidence'!A423",'Evidence'!D423) | C5: =HYPERLINK("#'Evidence'!A424",'Evidence'!D424) | D5: =HYPERLINK("#'Evidence'!A425",'Evidence'!D425) | E5: =HYPERLINK("#'Evidence'!A426",'Evidence'!D426) | F5: =HYPERLINK("#'Evidence'!A427",'Evidence'!D427) | G5: =HYPERLINK("#'Evidence'!A428",'Evidence'!D428) | H5: =HYPERLINK("#'Evidence'!A429",'Evidence'!D429) | I5: =HYPERLINK("#'Evidence'!A430",'Evidence'!D430) | K5: =HYPERLINK("#'Evidence'!A431",'Evidence'!D431) | L5: =HYPERLINK("#'Evidence'!A432",'Evidence'!D432) | M5: =HYPERLINK("#'Evidence'!A433",'Evidence'!D433) | N5: =HYPERLINK("#'Evidence'!A434",'Evidence'!D434)

Sheet Evidence
A1: evidence_id | B1: output_sheet | C1: output_cell | D1: value | E1: source_type | F1: source_table | G1: source_column | H1: source_record_id | I1: extraction_method | J1: extracted_at
A2: EV-000001 | B2: ALL | C2: A2 | D2: P001 | E2: database | F2: cord_ph_birth_records | G2: patient_code | H2: 1 | I2: sql_direct | J2: 2026-05-28T20:00:00Z
A3: EV-000002 | B3: ALL | C3: B2 | D3: 39 | E3: sql | F3: cord_ph_birth_records | G3: gestation_weeks | H3: CPH001 | I3: populate_region | J3: 2026-05-28T20:47:56.503917+00:00
A4: EV-000003 | B4: ALL | C4: C2 | D4: 4 | E4: sql | F4: cord_ph_birth_records | G4: gestation_days | H4: CPH001 | I4: populate_region | J4: 2026-05-28T20:47:56.503917+00:00
A5: EV-000004 | B5: ALL | C5: D2 | D5: 31 | E5: sql | F5: cord_ph_birth_records | G5: maternal_age | H5: CPH001 | I5: populate_region | J5: 2026-05-28T20:47:56.503917+00:00
A6: EV-000005 | B6: ALL | C6: E2 | D6: 1 | E6: sql | F6: cord_ph_birth_records | G6: parity | H6: CPH001 | I6: populate_region | J6: 2026-05-28T20:47:56.503917+00:00
A7: EV-000006 | B7: ALL | C7: G2 | D7: normal | E7: sql | F7: cord_ph_birth_records | G7: foetal_movements | H7: CPH001 | I7: populate_region | J7: 2026-05-28T20:47:56.503917+00:00
A8: EV-000007 | B8: ALL | C8: H2 | D8: none | E8: sql | F8: cord_ph_birth_records | G8: maternal_comorbidities | H8: CPH001 | I8: populate_region | J8: 2026-05-28T20:47:56.503917+00:00
A9: EV-000008 | B9: ALL | C9: I2 | E9: sql | F9: cord_ph_birth_records | G9: maternal_comorbidities_other | H9: CPH001 | I9: populate_region | J9: 2026-05-28T20:47:56.503917+00:00
A10: EV-000009 | B10: ALL | C10: J2 | D10: yes | E10: sql | F10: cord_ph_birth_records | G10: normal_scans | H10: CPH001 | I10: populate_region | J10: 2026-05-28T20:47:56.503917+00:00
A11: EV-000010 | B11: ALL | C11: K2 | D11: yes | E11: sql | F11: cord_ph_birth_records | G11: normal_dopplers | H11: CPH001 | I11: populate_region | J11: 2026-05-28T20:47:56.503917+00:00
A12: EV-000011 | B12: ALL | C12: M2 | D12: no | E12: sql | F12: cord_ph_birth_records | G12: ctg_done | H12: CPH001 | I12: populate_region | J12: 2026-05-28T20:47:56.503917+00:00
A13: EV-000012 | B13: ALL | C13: N2 | D13: no | E13: sql | F13: cord_ph_birth_records | G13: liquor_meconium | H13: CPH001 | I13: populate_region | J13: 2026-05-28T20:47:56.503917+00:00
A14: EV-000013 | B14: ALL | C14: O2 | D14: no | E14: sql | F14: cord_ph_birth_records | G14: chorioamnionitis | H14: CPH001 | I14: populate_region | J14: 2026-05-28T20:47:56.503917+00:00
A15: EV-000014 | B15: ALL | C15: P2 | D15: no | E15: sql | F15: cord_ph_birth_records | G15: prom_gt_18hours | H15: CPH001 | I15: populate_region | J15: 2026-05-28T20:47:56.503917+00:00
A16: EV-000015 | B16: ALL | C16: Q2 | D16: no | E16: sql | F16: cord_ph_birth_records | G16: rffs | H16: CPH001 | I16: populate_region | J16: 2026-05-28T20:47:56.503917+00:00
A17: EV-000016 | B17: ALL | C17: R2 | D17: no | E17: sql | F17: cord_ph_birth_records | G17: sentinel_event | H17: CPH001 | I17: populate_region | J17: 2026-05-28T20:47:56.503917+00:00
A18: EV-000017 | B18: ALL | C18: T2 | D18: Spontaneous vaginal | E18: sql | F18: cord_ph_birth_records | G18: delivery | H18: CPH001 | I18: populate_region | J18: 2026-05-28T20:47:56.503917+00:00
A19: EV-000018 | B19: ALL | C19: U2 | D19: 3420 | E19: sql | F19: cord_ph_birth_records | G19: birth_weight_grams | H19: CPH001 | I19: populate_region | J19: 2026-05-28T20:47:56.503917+00:00
A20: EV-000019 | B20: ALL | C20: V2 | D20: 8 | E20: sql | F20: cord_ph_birth_records | G20: apgars_1 | H20: CPH001 | I20: populate_region | J20: 2026-05-28T20:47:56.503917+00:00
A21: EV-000020 | B21: ALL | C21: W2 | D21: 9 | E21: sql | F21: cord_ph_birth_records | G21: apgars_5 | H21: CPH001 | I21: populate_region | J21: 2026-05-28T20:47:56.503917+00:00
A22: EV-000021 | B22: ALL | C22: X2 | E22: sql | F22: cord_ph_birth_records | G22: apgars_10 | H22: CPH001 | I22: populate_region | J22: 2026-05-28T20:47:56.503917+00:00
A23: EV-000022 | B23: ALL | C23: Y2 | D23: yes | E23: sql | F23: cord_ph_birth_records | G23: delayed_cord_clamping | H23: CPH001 | I23: populate_region | J23: 2026-05-28T20:47:56.503917+00:00
A24: EV-000023 | B24: ALL | C24: Z2 | D24: 7.28 | E24: sql | F24: cord_ph_birth_records | G24: cord_arterial_ph | H24: CPH001 | I24: populate_region | J24: 2026-05-28T20:47:56.503917+00:00
A25: EV-000024 | B25: ALL | C25: AA2 | D25: -3.4 | E25: sql | F25: cord_ph_birth_records | G25: cord_arterial_be | H25: CPH001 | I25: populate_region | J25: 2026-05-28T20:47:56.503917+00:00
A26: EV-000025 | B26: ALL | C26: AB2 | D26: 3.1 | E26: sql | F26: cord_ph_birth_records | G26: cord_arterial_lactate | H26: CPH001 | I26: populate_region | J26: 2026-05-28T20:47:56.503917+00:00
A27: EV-000026 | B27: ALL | C27: AD2 | D27: no | E27: sql | F27: cord_ph_birth_records | G27: intubated_at_delivery | H27: CPH001 | I27: populate_region | J27: 2026-05-28T20:47:56.503917+00:00
A28: EV-000027 | B28: ALL | C28: AE2 | D28: no | E28: sql | F28: cord_ph_birth_records | G28: cardiac_compressions | H28: CPH001 | I28: populate_region | J28: 2026-05-28T20:47:56.503917+00:00
A29: EV-000028 | B29: ALL | C29: AF2 | D29: no | E29: sql | F29: cord_ph_birth_records | G29: drugs_given | H29: CPH001 | I29: populate_region | J29: 2026-05-28T20:47:56.503917+00:00
A30: EV-000029 | B30: ALL | C30: AG2 | D30: Postnatal ward | E30: sql | F30: cord_ph_birth_records | G30: ward | H30: CPH001 | I30: populate_region | J30: 2026-05-28T20:47:56.503917+00:00
A31: EV-000030 | B31: ALL | C31: AH2 | D31: no | E31: sql | F31: cord_ph_birth_records | G31: gas_repeated | H31: CPH001 | I31: populate_region | J31: 2026-05-28T20:47:56.503917+00:00
A32: EV-000031 | B32: ALL | C32: AI2 | E32: sql | F32: cord_ph_birth_records | G32: age_at_repeated_gas_hours | H32: CPH001 | I32: populate_region | J32: 2026-05-28T20:47:56.503917+00:00
A33: EV-000032 | B33: ALL | C33: AJ2 | E33: sql | F33: cord_ph_birth_records | G33: repeated_lactate | H33: CPH001 | I33: populate_region | J33: 2026-05-28T20:47:56.503917+00:00
A34: EV-000033 | B34: ALL | C34: AK2 | E34: sql | F34: cord_ph_birth_records | G34: age_gas_normalised_hours | H34: CPH001 | I34: populate_region | J34: 2026-05-28T20:47:56.503917+00:00
A35: EV-000034 | B35: ALL | C35: AL2 | D35: no | E35: sql | F35: cord_ph_birth_records | G35: hypoglycaemia | H35: CPH001 | I35: populate_region | J35: 2026-05-28T20:47:56.503917+00:00
A36: EV-000035 | B36: ALL | C36: AM2 | D36: no | E36: sql | F36: cord_ph_birth_records | G36: admitted_to_nicu | H36: CPH001 | I36: populate_region | J36: 2026-05-28T20:47:56.503917+00:00
A37: EV-000036 | B37: ALL | C37: AN2 | D37: 2 | E37: sql | F37: cord_ph_birth_records | G37: age_at_discharge_home_days | H37: CPH001 | I37: populate_region | J37: 2026-05-28T20:47:56.503917+00:00
A38: EV-000037 | B38: ALL | C38: AO2 | D38: yes | E38: sql | F38: cord_ph_birth_records | G38: unit_level_questionnaire_filled | H38: CPH001 | I38: populate_region | J38: 2026-05-28T20:47:56.503917+00:00
A39: EV-000038 | B39: ALL | C39: AP2 | D39: yes | E39: sql | F39: cord_ph_birth_records | G39: local_guideline_for_cord_gas_sampling_available | H39: CPH001 | I39: populate_region | J39: 2026-05-28T20:47:56.503917+00:00
A40: EV-000039 | B40: ALL | C40: AQ2 | D40: yes | E40: sql | F40: cord_ph_birth_records | G40: local_guideline_for_fetal_acidosis_available | H40: CPH001 | I40: populate_region | J40: 2026-05-28T20:47:56.503917+00:00
...
